<?xml version="1.0"?>
<!-- This URDF was automatically created by SolidWorks to URDF Exporter! Originally created by Stephen Brawner (brawner@gmail.com) 
     Commit Version: 1.6.0-4-g7f85cfe  Build Version: 1.6.7995.38578
     For more information, please see http://wiki.ros.org/sw_urdf_exporter -->
<robot
  name="agv_ros">
  <link
    name="base_link">
    <inertial>
      <origin
        xyz="-0.00119053906143674 0.000176947403296851 0.0585575515702573"
        rpy="0 0 0" />
      <mass
        value="10" />
      <inertia
        ixx="0.000488430356749696"
        ixy="-1.61674760552789E-07"
        ixz="8.89340811442663E-06"
        iyy="0.000735532461305397"
        iyz="-2.79410615597662E-07"
        izz="0.00104164866364385" />
    </inertial>
    <visual>
      <origin
        xyz="0 0 0"
        rpy="0 0 0" />
      <geometry>
        <mesh
          filename="package://agv_ros/meshes/base_link.STL" />
      </geometry>
      <material
        name="">
        <color
          rgba="0.270588235294118 0.270588235294118 0.270588235294118 1" />
      </material>
    </visual>
    <collision>
      <origin
        xyz="0 0 0"
        rpy="0 0 0" />
      <geometry>
        <mesh
          filename="package://agv_ros/meshes/base_link.STL" />
      </geometry>
    </collision>
  </link>
  <link
    name="front_left">
    <inertial>
      <origin
        xyz="3.34415344401297E-05 -0.0165234096739332 -9.96715808939883E-06"
        rpy="0 0 0" />
      <mass
        value="0.0462990889731472" />
      <inertia
        ixx="5.02475713243527E-06"
        ixy="-7.07388466172052E-10"
        ixz="4.51430128435127E-10"
        iyy="6.32652725267394E-06"
        iyz="-8.2614230705414E-10"
        izz="5.02489742459376E-06" />
    </inertial>
    <visual>
      <origin
        xyz="0 0 0"
        rpy="0 0 0" />
      <geometry>
        <mesh
          filename="package://agv_ros/meshes/front_left.STL" />
      </geometry>
      <material
        name="">
        <color
          rgba="0.301960784313725 0.301960784313725 0.301960784313725 1" />
      </material>
    </visual>
    <collision>
      <origin
        xyz="0 0 0"
        rpy="1.5708 0 0" />
      <geometry>
        <cylinder
          radius="0.05"
          length="0.03" />
      </geometry>
    </collision>
  </link>
  <joint
    name="Frontleft_joint"
    type="continuous">
    <origin
      xyz="0.0468000000000123 0.0794634000000287 -0.017779999999999"
      rpy="0 0 0" />
    <parent
      link="base_link" />
    <child
      link="front_left" />
    <axis
      xyz="0 -1 0" />
    <limit
      effort="50"
      velocity="10" />
    <dynamics
      damping="0.01"
      friction="0.0" />
  </joint>
  <link
    name="front_right">
    <inertial>
      <origin
        xyz="-3.55772632004703E-06 0.0165234096670951 -3.47134566110775E-05"
        rpy="0 0 0" />
      <mass
        value="0.0462990890135422" />
      <inertia
        ixx="5.02519558755712E-06"
        ixy="-1.03365233612496E-09"
        ixz="2.7025083922104E-10"
        iyy="6.32652724612357E-06"
        iyz="-3.38330489866918E-10"
        izz="5.024458969259E-06" />
    </inertial>
    <visual>
      <origin
        xyz="0 0 0"
        rpy="0 0 0" />
      <geometry>
        <mesh
          filename="package://agv_ros/meshes/front_right_mirrored.STL" />
      </geometry>
      <material
        name="">
        <color
          rgba="0.301960784313725 0.301960784313725 0.301960784313725 1" />
      </material>
    </visual>
    <collision>
      <origin
        xyz="0 0 0"
        rpy="1.5708 0 0" />
      <geometry>
        <cylinder
          radius="0.05"
          length="0.03" />
      </geometry>
    </collision>
  </link>
  <joint
    name="FrontRight_joint"
    type="continuous">
    <origin
      xyz="0.0467999999999944 -0.0798228000000289 -0.017780000000011"
      rpy="0 0 0" />
    <parent
      link="base_link" />
    <child
      link="front_right" />
    <axis
      xyz="0 1 0" />
    <limit
      effort="50"
      velocity="10" />
    <dynamics
      damping="0.01"
      friction="0.0" />
  </joint>
  <link
    name="back_left">
    <inertial>
      <origin
        xyz="3.34415344113298E-05 -0.0165234096739332 -9.96715808100276E-06"
        rpy="0 0 3.14159" />
      <mass
        value="0.0462990889731472" />
      <inertia
        ixx="5.02475713243527E-06"
        ixy="-7.07388466171891E-10"
        ixz="4.51430128434854E-10"
        iyy="6.32652725267394E-06"
        iyz="-8.26142307053987E-10"
        izz="5.02489742459376E-06" />
    </inertial>
    <visual>
      <origin
        xyz="0 0 0"
        rpy="0 0 3.14159" />
      <geometry>
        <mesh
          filename="package://agv_ros/meshes/back_left_mirrored.STL" />
      </geometry>
      <material
        name="">
        <color
          rgba="0.301960784313725 0.301960784313725 0.301960784313725 1" />
      </material>
    </visual>
    <collision>
      <origin
        xyz="0 0 0"
        rpy="1.5708 0 0" />
      <geometry>
        <cylinder
          radius="0.05"
          length="0.03" />
      </geometry>
    </collision>
  </link>
  <joint
    name="BackLeft_joint"
    type="continuous">
    <origin
      xyz="-0.0453003999999591 0.0794634000000286 -0.0177800000000074"
      rpy="0 0 0" />
    <parent
      link="base_link" />
    <child
      link="back_left" />
    <axis
      xyz="0 -1 0" />
    <limit
      effort="50"
      velocity="10" />
    <dynamics
      damping="0.01"
      friction="0.0" />
  </joint>
  <link
    name="back_right">
    <inertial>
      <origin
        xyz="-3.55772632003315E-06 0.0165234096670951 -3.47134566110498E-05"
        rpy="0 0 0" />
      <mass
        value="0.0462990890135422" />
      <inertia
        ixx="5.02519558755712E-06"
        ixy="-1.03365233612524E-09"
        ixz="2.70250839219757E-10"
        iyy="6.32652724612357E-06"
        iyz="-3.38330489866705E-10"
        izz="5.024458969259E-06" />
    </inertial>
    <visual>
      <origin
        xyz="0 0 0"
        rpy="0 0 0" />
      <geometry>
        <mesh
          filename="package://agv_ros/meshes/back_right.STL" />
      </geometry>
      <material
        name="">
        <color
          rgba="0.301960784313725 0.301960784313725 0.301960784313725 1" />
      </material>
    </visual>
    <collision>
      <origin
        xyz="0 0 0"
        rpy="1.5708 0 0" />
      <geometry>
        <cylinder
          radius="0.05"
          length="0.03" />
      </geometry>
    </collision>
  </link>
  <joint
    name="BackRight_joint"
    type="continuous">
    <origin
      xyz="-0.0453004000000056 -0.0798228000000288 -0.017780000000011"
      rpy="0 0 0" />
    <parent
      link="base_link" />
    <child
      link="back_right" />
    <axis
      xyz="0 1 0" />
    <limit
      effort="50"
      velocity="10" />
    <dynamics
      damping="0.01"
      friction="0.0" />
  </joint>
  <link
    name="lidar">
    <inertial>
      <origin
        xyz="8.75598307271686E-05 2.45719922700033E-05 0.0136799210635855"
        rpy="0 0 0" />
      <mass
        value="0.0898604100581048" />
      <inertia
        ixx="2.85627915714696E-05"
        ixy="-6.06790188056003E-08"
        ixz="2.13425384222246E-08"
        iyy="2.8761600068061E-05"
        iyz="6.03457647574362E-09"
        izz="4.62610264513428E-05" />
    </inertial>
    <visual>
      <origin
        xyz="0 0 0"
        rpy="0 0 0" />
      <geometry>
        <mesh
          filename="package://agv_ros/meshes/lidar.STL" />
      </geometry>
      <material
        name="">
        <color
          rgba="0.792156862745098 0.819607843137255 0.933333333333333 1" />
      </material>
    </visual>
    <collision>
      <origin
        xyz="0 0 0"
        rpy="0 0 0" />
      <geometry>
        <mesh
          filename="package://agv_ros/meshes/lidar.STL" />
      </geometry>
    </collision>
  </link>
  <joint
    name="Lidar_joint"
    type="fixed">
    <origin
      xyz="-0.0092064 0 0.10442"
      rpy="0 0 0" />
    <parent
      link="base_link" />
    <child
      link="lidar" />
    <axis
      xyz="0 0 0" />
    <dynamics
      damping="0.1"
      friction="10" />
  </joint>
  <link
    name="gps_joint">
    <inertial>
      <origin
        xyz="0.000694977460061641 -2.42915511064479E-06 -3.32643991463738E-06"
        rpy="0 0 0" />
      <mass
        value="0.000935319530363505" />
      <inertia
        ixx="9.62520585676608E-08"
        ixy="3.44346358031668E-12"
        ixz="-1.03882523842337E-13"
        iyy="5.7335346190715E-08"
        iyz="-9.18412331237469E-13"
        izz="3.93390740510555E-08" />
    </inertial>
    <visual>
      <origin
        xyz="0 0 0"
        rpy="0 0 0" />
      <geometry>
        <mesh
          filename="package://agv_ros/meshes/gps_joint.STL" />
      </geometry>
      <material
        name="">
        <color
          rgba="0.792156862745098 0.819607843137255 0.933333333333333 1" />
      </material>
    </visual>
    <collision>
      <origin
        xyz="0 0 0"
        rpy="0 0 0" />
      <geometry>
        <mesh
          filename="package://agv_ros/meshes/gps_joint.STL" />
      </geometry>
    </collision>
  </link>
  <joint
    name="GPS_joint"
    type="fixed">
    <origin
      xyz="0.10433 -0.0425 0.059456"
      rpy="0 0 0" />
    <parent
      link="base_link" />
    <child
      link="gps_joint" />
    <axis
      xyz="0 0 0" />
    <dynamics
      damping="0.1"
      friction="10" />
  </joint>
  <link
    name="camera_joint">
    <inertial>
      <origin
        xyz="-0.00348876218866281 0.000258238879071997 0.000266655846504031"
        rpy="0 0 0" />
      <mass
        value="0.0261448047763111" />
      <inertia
        ixx="9.35012569687527E-06"
        ixy="-3.12138622466714E-08"
        ixz="1.49324787665759E-08"
        iyy="2.06103630560299E-06"
        iyz="-3.26028865535605E-09"
        izz="8.52413750211695E-06" />
    </inertial>
    <visual>
      <origin
        xyz="0 0 0"
        rpy="0 0 0" />
      <geometry>
        <mesh
          filename="package://agv_ros/meshes/camera_joint.STL" />
      </geometry>
      <material
        name="">
        <color
          rgba="0.792156862745098 0.819607843137255 0.933333333333333 1" />
      </material>
    </visual>
    <collision>
      <origin
        xyz="0 0 0"
        rpy="0 0 0" />
      <geometry>
        <mesh
          filename="package://agv_ros/meshes/camera_joint.STL" />
      </geometry>
    </collision>
  </link>
  <joint
    name="Camera_joint"
    type="fixed">
    <origin
      xyz="0.104334292145 0.0165 0.0594555999999996"
      rpy="0 0 0" />
    <parent
      link="base_link" />
    <child
      link="camera_joint" />
    <axis
      xyz="0 0 0" />
    <dynamics
      damping="0.1"
      friction="10" />
  </joint>
  <link
    name="basearm">
    <inertial>
      <origin
        xyz="9.22739665732975E-05 -1.25701476214046E-06 0.00255267654186053"
        rpy="0 0 0" />
      <mass
        value="0.0296332406525964" />
      <inertia
        ixx="1.36039293241669E-05"
        ixy="-7.38500887504922E-15"
        ixz="4.14469205725875E-09"
        iyy="1.37249913080232E-05"
        iyz="1.72234751921517E-17"
        izz="2.71729039784413E-05" />
    </inertial>
    <visual>
      <origin
        xyz="0 0 0"
        rpy="0 0 0" />
      <geometry>
        <mesh
          filename="package://agv_ros/meshes/basearm.STL" />
      </geometry>
      <material
        name="">
        <color
          rgba="0.749019607843137 0.749019607843137 0.749019607843137 1" />
      </material>
    </visual>
    <collision>
      <origin
        xyz="0 0 0"
        rpy="0 0 0" />
      <geometry>
        <mesh
          filename="package://agv_ros/meshes/basearm.STL" />
      </geometry>
    </collision>
  </link>
  <joint
    name="BaseArm"
    type="fixed">
    <origin
      xyz="-0.00921832440323599 0 0.143150698447992"
      rpy="0 0 0" />
    <parent
      link="base_link" />
    <child
      link="basearm" />
    <axis
      xyz="0 0 0" />
  </joint>
  <link
    name="arm_joint1">
    <inertial>
      <origin
        xyz="0.0388842012092648 -0.00158881731775529 0.0623511158104539"
        rpy="0 0 0" />
      <mass
        value="0.270186283992713" />
      <inertia
        ixx="0.000507722802221126"
        ixy="9.88499769226239E-06"
        ixz="-0.000358904472187945"
        iyy="0.000841441845785256"
        iyz="1.08994851899646E-05"
        izz="0.000410938661062764" />
    </inertial>
    <visual>
      <origin
        xyz="0 0 0"
        rpy="0 0 0" />
      <geometry>
        <mesh
          filename="package://agv_ros/meshes/arm_joint1.STL" />
      </geometry>
      <material
        name="">
        <color
          rgba="0.67843137254902 0.67843137254902 0.67843137254902 1" />
      </material>
    </visual>
    <collision>
      <origin
        xyz="0 0 0"
        rpy="0 0 0" />
      <geometry>
        <mesh
          filename="package://agv_ros/meshes/arm_joint1.STL" />
      </geometry>
    </collision>
  </link>
  <joint
    name="Arm_joint1"
    type="continuous">
    <origin
      xyz="0 0 0.00508"
      rpy="0 0 0" />
    <parent
      link="basearm" />
    <child
      link="arm_joint1" />
    <axis
      xyz="0 0 1" />
    <limit
      effort="10.0"
      velocity="1.5" />
    <dynamics
      damping="0.1"
      friction="10" />
  </joint>
  <link
    name="arm_joint2">
    <inertial>
      <origin
        xyz="0.0253172488394307 -0.0266087058656372 0.00330822591848871"
        rpy="0 0 0" />
      <mass
        value="0.0533454706493746" />
      <inertia
        ixx="7.27072522722006E-05"
        ixy="5.84025157696102E-05"
        ixz="-2.17855487483276E-07"
        iyy="5.9127688488704E-05"
        iyz="2.89033837690945E-07"
        izz="0.000129815886292191" />
    </inertial>
    <visual>
      <origin
        xyz="0 0 0"
        rpy="0 0 0" />
      <geometry>
        <mesh
          filename="package://agv_ros/meshes/arm_joint2.STL" />
      </geometry>
      <material
        name="">
        <color
          rgba="0.67843137254902 0.67843137254902 0.67843137254902 1" />
      </material>
    </visual>
    <collision>
      <origin
        xyz="0 0 0"
        rpy="0 0 0" />
      <geometry>
        <mesh
          filename="package://agv_ros/meshes/arm_joint2.STL" />
      </geometry>
    </collision>
  </link>
  <joint
    name="Arm_joint2"
    type="revolute">
    <origin
      xyz="0.075316 -0.022291 0.10414"
      rpy="1.5708 0 0" />
    <parent
      link="arm_joint1" />
    <child
      link="arm_joint2" />
    <axis
      xyz="0.042759 0 -0.99909" />
    <limit
      lower="-1.75"
      upper="0.593"
      effort="10.0"
      velocity="1.0" />
    <dynamics
      damping="0.1"
      friction="10" />
  </joint>
  
<link name="camera_link_optical"></link>

  <joint name="camera_optical_joint" type="fixed">
    <origin xyz="0 0 0" rpy="-1.5708 0 -1.5708"/>
    <parent link="camera_joint"/>
    <child link="camera_link_optical"/>
  </joint>
  
  <gazebo reference="camera_joint">
    <sensor type="camera" name="my_camera">
      <update_rate>30.0</update_rate>
      <visualize>true</visualize> 
      <camera name="head">
        <horizontal_fov>1.08</horizontal_fov>
        <image>
          <width>800</width>
          <height>800</height>
          <format>R8G8B8</format>
        </image>
        <clip>
          <near>0.02</near>
          <far>50</far>
        </clip>
      </camera>
      <plugin name="camera_controller" filename="libgazebo_ros_camera.so">
        <ros>
          <namespace>/</namespace>
          <remapping>image_raw:=custom_camera/image_raw</remapping>
          <remapping>camera_info:=custom_camera/camera_info</remapping>
        </ros>
        <frame_name>camera_link_optical</frame_name> 
      </plugin>
    </sensor>
  </gazebo>
  
  <gazebo reference="lidar">
    <sensor type="ray" name="head_hokuyo_sensor">
      <pose>0 0 0 0 0 0</pose>
      <visualize>true</visualize>
      <update_rate>10</update_rate>
      <ray>
        <scan>
          <horizontal>
            <samples>360</samples>
            <resolution>1</resolution>
            <min_angle>-3.14159</min_angle>
            <max_angle>3.14159</max_angle>
          </horizontal>
        </scan>
        <range>
          <min>0.10</min>
          <max>12.0</max>
          <resolution>0.01</resolution>
        </range>
        <noise>
          <type>gaussian</type>
          <mean>0.0</mean>
          <stddev>0.01</stddev>
        </noise>
      </ray>
      <plugin name="gazebo_ros_laser_controller" filename="libgazebo_ros_ray_sensor.so">
        <ros>
          <remapping>~/out:=scan</remapping>
        </ros>
        <output_type>sensor_msgs/LaserScan</output_type>
        <frame_name>lidar</frame_name>
      </plugin>
    </sensor>
  </gazebo>



 <gazebo reference="front_left">
    <mu1>0.2</mu1>
    <mu2>0.2</mu2>
    <kp>1000000.0</kp>
    <kd>100.0</kd>
    <minDepth>0.001</minDepth>
    <material>Gazebo/Grey</material>
  </gazebo>

  <gazebo reference="front_right">
    <mu1>0.2</mu1>
    <mu2>0.2</mu2>
    <kp>1000000.0</kp>
    <kd>100.0</kd>
    <minDepth>0.001</minDepth>
    <material>Gazebo/Grey</material>
  </gazebo>

  <gazebo reference="back_left">
    <mu1>0.2</mu1>
    <mu2>0.2</mu2>
    <kp>1000000.0</kp>
    <kd>100.0</kd>
    <minDepth>0.001</minDepth>
    <material>Gazebo/Grey</material>
  </gazebo>

  <gazebo reference="back_right">
    <mu1>0.2</mu1>
    <mu2>0.2</mu2>
    <kp>1000000.0</kp>
    <kd>100.0</kd>
    <minDepth>0.001</minDepth>
    <material>Gazebo/Grey</material>
  </gazebo>

  <gazebo reference="gps_joint">
    <sensor name="agv_gps" type="gps">
      <always_on>true</always_on>
      <update_rate>1.0</update_rate>
      <plugin name="gps_controller" filename="libgazebo_ros_gps_sensor.so">
        <ros>
          <remapping>~/out:=gps/data</remapping>
        </ros>
        <frame_name>gps_joint</frame_name>
      </plugin>
    </sensor>
  </gazebo>

  <ros2_control name="gazebo_arm_control" type="system">
    <hardware>
      <plugin>gazebo_ros2_control/GazeboSystem</plugin>
    </hardware>
    <joint name="Frontleft_joint">
      <command_interface name="velocity"/>
      <state_interface name="position"/>
      <state_interface name="velocity"/>
    </joint>
    <joint name="FrontRight_joint">
      <command_interface name="velocity"/>
      <state_interface name="position"/>
      <state_interface name="velocity"/>
    </joint>
    <joint name="BackLeft_joint">
      <command_interface name="velocity"/>
      <state_interface name="position"/>
      <state_interface name="velocity"/>
    </joint>
    <joint name="BackRight_joint">
      <command_interface name="velocity"/>
      <state_interface name="position"/>
      <state_interface name="velocity"/>
    </joint>
    <joint name="Arm_joint1">
      <command_interface name="position"/>
      <state_interface name="position"/>
      <state_interface name="velocity"/>
    </joint>
    <joint name="Arm_joint2">
      <command_interface name="position"/>
      <state_interface name="position"/>
      <state_interface name="velocity"/>
    </joint>
  </ros2_control>

  <gazebo>
    <plugin name="gazebo_ros_planar_move" filename="libgazebo_ros_planar_move.so">
      <ros>
        <namespace>/</namespace>
        <remapping>cmd_vel:=cmd_vel</remapping>
        <remapping>odometry:=odom</remapping>
      </ros>
      <update_rate>50.0</update_rate>
      <body_name>base_link</body_name>
      <odometry_frame>odom</odometry_frame>
      <robot_base_frame>base_link</robot_base_frame>
    </plugin>
    <plugin name="gazebo_ros2_control" filename="libgazebo_ros2_control.so">
      <parameters>__ARM_CONTROLLER_CONFIG__</parameters>
    </plugin>
  </gazebo>
  
  
  
</robot>
